File: example_files/Gonio_BBHD_Galipix[20-80]_W1X1-1.csv
[Measurement conditions]
Sample identification,W1X1-1
Comment - 1,"Configuration=Chi-Phi-x-y-z stage, Owner=User-1, Creation date=2/8/2017 9:11:14 AM"
Comment - 2,"Goniometer=Theta/Theta; Minimum step size 2Theta:0.0001; Minimum step size Omega:0.0001"
Comment - 3,"Sample stage=Chi-Phi-x-y-z stage 240 mm; Minimum step size Phi:0.01; Minimum step size Chi:0.01; Minimum step size X:0.01; Minimum step size Y:0.01; Minimum step size Z:0.001"
Comment - 4,"Diffractometer system=EMPYREAN"
Comment - 5,"Measurement program=C:\PANalytical\Data Collector\Programs\Nathan Johnson\Ti64 Programs\Gonio_BBHD_Galipix[20-80].xrdmp, Identifier={F67B0DEB-5B12-4279-AED5-32372170C152}"
Anode material,Cu
K-Alpha1 wavelength,1.5405980
K-Alpha2 wavelength,1.5444260
Ratio K-Alpha2/K-Alpha1,0.500
Divergence slit,Fixed,0.19mm
Monochromator used,NO
Generator voltage, 45
Tube current, 40
File date and time,07/Feb/2018 09:43
Unit cell,
h k l, 0 0 0
Scan axis,2Theta-Omega
Scan range,20.011399996,80.000079494
Scan step size,0.0286479
Omega offset,0.00000000
No. of points, 2094
Scan type,CONTINUOUS
Phi,0.00
Psi,0.00
X,1.17
Y,2.42
Z,1.302
Time per step,50.100
[Scan points]
Angle,Intensity
20.025723940,577.0
20.083019718,604.0
20.140315496,636.0
20.197611274,637.0
20.254907052,607.0
20.312202830,615.0
20.369498608,622.0
20.426794386,543.0
20.484090163,584.0
20.541385941,575.0
20.598681719,578.0
20.655977497,574.0
20.713273275,573.0
20.770569053,549.0
20.827864831,547.0
20.885160609,552.0
20.942456387,590.0
20.999752165,551.0
21.057047943,499.0
21.114343721,581.0
21.171639499,545.0
21.228935277,514.0
21.286231055,572.0
21.343526833,528.0
21.400822610,477.0
21.458118388,495.0
21.515414166,508.0
21.572709944,519.0
21.630005722,507.0
21.687301500,463.0
21.744597278,498.0
21.801893056,515.0
21.859188834,487.0
21.916484612,447.0
21.973780390,448.0
22.031076168,406.0
22.088371946,473.0
22.145667724,505.0
22.202963502,441.0
22.260259280,464.0
22.317555057,442.0
22.374850835,424.0
22.432146613,454.0
22.489442391,389.0
22.546738169,461.0
22.604033947,437.0
22.661329725,416.0
22.718625503,479.0
22.775921281,431.0
22.833217059,415.0
22.890512837,422.0
22.947808615,414.0
23.005104393,460.0
23.062400171,361.0
23.119695949,391.0
23.176991726,417.0
23.234287504,412.0
23.291583282,409.0
23.348879060,413.0
23.406174838,430.0
23.463470616,408.0
23.520766394,426.0
23.578062172,393.0
23.635357950,379.0
23.692653728,341.0
23.749949506,406.0
23.807245284,356.0
23.864541062,367.0
23.921836840,388.0
23.979132618,376.0
24.036428396,367.0
24.093724173,351.0
24.151019951,354.0
24.208315729,345.0
24.265611507,330.0
24.322907285,333.0
24.380203063,363.0
24.437498841,326.0
24.494794619,340.0
24.552090397,345.0
24.609386175,336.0
24.666681953,341.0
24.723977731,343.0
24.781273509,336.0
24.838569287,311.0
24.895865065,373.0
24.953160842,334.0
25.010456620,319.0
25.067752398,351.0
25.125048176,314.0
25.182343954,306.0
25.239639732,318.0
25.296935510,314.0
25.354231288,295.0
25.411527066,271.0
25.468822844,328.0
25.526118622,323.0
25.583414400,307.0
25.640710178,287.0
25.698005956,295.0
25.755301734,304.0
25.812597512,294.0
25.869893289,315.0
25.927189067,302.0
25.984484845,272.0
26.041780623,271.0
26.099076401,296.0
26.156372179,280.0
26.213667957,280.0
26.270963735,290.0
26.328259513,289.0
26.385555291,273.0
26.442851069,304.0
26.500146847,291.0
26.557442625,272.0
26.614738403,279.0
26.672034181,303.0
26.729329959,267.0
26.786625736,277.0
26.843921514,257.0
26.901217292,268.0
26.958513070,260.0
27.015808848,281.0
27.073104626,256.0
27.130400404,294.0
27.187696182,242.0
27.244991960,240.0
27.302287738,281.0
27.359583516,271.0
27.416879294,250.0
27.474175072,274.0
27.531470850,264.0
27.588766628,211.0
27.646062405,288.0
27.703358183,251.0
27.760653961,276.0
27.817949739,248.0
27.875245517,225.0
27.932541295,233.0
27.989837073,245.0
28.047132851,223.0
28.104428629,225.0
28.161724407,241.0
28.219020185,236.0
28.276315963,245.0
28.333611741,220.0
28.390907519,236.0
28.448203297,224.0
28.505499075,214.0
28.562794852,212.0
28.620090630,211.0
28.677386408,239.0
28.734682186,219.0
28.791977964,232.0
28.849273742,207.0
28.906569520,229.0
28.963865298,223.0
29.021161076,207.0
29.078456854,229.0
29.135752632,213.0
29.193048410,207.0
29.250344188,215.0
29.307639966,203.0
29.364935744,197.0
29.422231522,230.0
29.479527299,220.0
29.536823077,203.0
29.594118855,203.0
29.651414633,212.0
29.708710411,218.0
29.766006189,190.0
29.823301967,186.0
29.880597745,202.0
29.937893523,206.0
29.995189301,207.0
30.052485079,226.0
30.109780857,212.0
30.167076635,182.0
30.224372413,212.0
30.281668191,196.0
30.338963968,205.0
30.396259746,215.0
30.453555524,188.0
30.510851302,207.0
30.568147080,199.0
30.625442858,202.0
30.682738636,191.0
30.740034414,207.0
30.797330192,190.0
30.854625970,166.0
30.911921748,183.0
30.969217526,183.0
31.026513304,210.0
31.083809082,210.0
31.141104860,188.0
31.198400638,165.0
31.255696415,205.0
31.312992193,175.0
31.370287971,196.0
31.427583749,161.0
31.484879527,193.0
31.542175305,195.0
31.599471083,191.0
31.656766861,192.0
31.714062639,198.0
31.771358417,171.0
31.828654195,193.0
31.885949973,181.0
31.943245751,160.0
32.000541529,182.0
32.057837307,185.0
32.115133084,159.0
32.172428862,180.0
32.229724640,183.0
32.287020418,168.0
32.344316196,170.0
32.401611974,167.0
32.458907752,150.0
32.516203530,163.0
32.573499308,157.0
32.630795086,147.0
32.688090864,145.0
32.745386642,162.0
32.802682420,156.0
32.859978198,170.0
32.917273976,160.0
32.974569754,182.0
33.031865531,142.0
33.089161309,152.0
33.146457087,138.0
33.203752865,167.0
33.261048643,136.0
33.318344421,155.0
33.375640199,144.0
33.432935977,153.0
33.490231755,161.0
33.547527533,193.0
33.604823311,160.0
33.662119089,151.0
33.719414867,136.0
33.776710645,176.0
33.834006423,165.0
33.891302201,161.0
33.948597978,157.0
34.005893756,139.0
34.063189534,152.0
34.120485312,158.0
34.177781090,154.0
34.235076868,158.0
34.292372646,157.0
34.349668424,158.0
34.406964202,150.0
34.464259980,135.0
34.521555758,143.0
34.578851536,175.0
34.636147314,136.0
34.693443092,157.0
34.750738870,154.0
34.808034647,156.0
34.865330425,152.0
34.922626203,143.0
34.979921981,154.0
35.037217759,149.0
35.094513537,149.0
35.151809315,164.0
35.209105093,163.0
35.266400871,139.0
35.323696649,140.0
35.380992427,152.0
35.438288205,171.0
35.495583983,144.0
35.552879761,138.0
35.610175539,143.0
35.667471317,134.0
35.724767094,130.0
35.782062872,133.0
35.839358650,145.0
35.896654428,146.0
35.953950206,143.0
36.011245984,152.0
36.068541762,116.0
36.125837540,123.0
36.183133318,107.0
36.240429096,140.0
36.297724874,152.0
36.355020652,122.0
36.412316430,140.0
36.469612208,140.0
36.526907986,156.0
36.584203763,152.0
36.641499541,121.0
36.698795319,161.0
36.756091097,131.0
36.813386875,144.0
36.870682653,147.0
36.927978431,138.0
36.985274209,149.0
37.042569987,158.0
37.099865765,140.0
37.157161543,133.0
37.214457321,138.0
37.271753099,138.0
37.329048877,134.0
37.386344655,107.0
37.443640433,133.0
37.500936210,140.0
37.558231988,133.0
37.615527766,133.0
37.672823544,146.0
37.730119322,134.0
37.787415100,127.0
37.844710878,152.0
37.902006656,117.0
37.959302434,130.0
38.016598212,117.0
38.073893990,134.0
38.131189768,139.0
38.188485546,146.0
38.245781324,134.0
38.303077102,124.0
38.360372880,155.0
38.417668657,136.0
38.474964435,153.0
38.532260213,141.0
38.589555991,145.0
38.646851769,165.0
38.704147547,157.0
38.761443325,109.0
38.818739103,132.0
38.876034881,131.0
38.933330659,136.0
38.990626437,142.0
39.047922215,124.0
39.105217993,132.0
39.162513771,111.0
39.219809549,133.0
39.277105326,134.0
39.334401104,153.0
39.391696882,151.0
39.448992660,131.0
39.506288438,128.0
39.563584216,113.0
39.620879994,140.0
39.678175772,129.0
39.735471550,156.0
39.792767328,130.0
39.850063106,140.0
39.907358884,126.0
39.964654662,137.0
40.021950440,136.0
40.079246218,171.0
40.136541996,154.0
40.193837773,204.0
40.251133551,232.0
40.308429329,367.0
40.365725107,592.0
40.423020885,792.0
40.480316663,711.0
40.537612441,592.0
40.594908219,366.0
40.652203997,210.0
40.709499775,170.0
40.766795553,153.0
40.824091331,125.0
40.881387109,133.0
40.938682887,114.0
40.995978665,123.0
41.053274443,123.0
41.110570220,129.0
41.167865998,131.0
41.225161776,123.0
41.282457554,119.0
41.339753332,117.0
41.397049110,124.0
41.454344888,120.0
41.511640666,114.0
41.568936444,110.0
41.626232222,119.0
41.683528000,108.0
41.740823778,112.0
41.798119556,119.0
41.855415334,113.0
41.912711112,116.0
41.970006889,134.0
42.027302667,116.0
42.084598445,124.0
42.141894223,122.0
42.199190001,130.0
42.256485779,107.0
42.313781557,106.0
42.371077335,113.0
42.428373113,131.0
42.485668891,111.0
42.542964669,114.0
42.600260447,109.0
42.657556225,124.0
42.714852003,119.0
42.772147781,102.0
42.829443559,97.0
42.886739336,89.0
42.944035114,114.0
43.001330892,116.0
43.058626670,116.0
43.115922448,111.0
43.173218226,108.0
43.230514004,97.0
43.287809782,101.0
43.345105560,112.0
43.402401338,103.0
43.459697116,99.0
43.516992894,107.0
43.574288672,105.0
43.631584450,101.0
43.688880228,108.0
43.746176005,121.0
43.803471783,108.0
43.860767561,117.0
43.918063339,115.0
43.975359117,96.0
44.032654895,128.0
44.089950673,98.0
44.147246451,119.0
44.204542229,99.0
44.261838007,98.0
44.319133785,108.0
44.376429563,113.0
44.433725341,91.0
44.491021119,110.0
44.548316897,114.0
44.605612675,105.0
44.662908452,104.0
44.720204230,116.0
44.777500008,96.0
44.834795786,105.0
44.892091564,104.0
44.949387342,104.0
45.006683120,96.0
45.063978898,112.0
45.121274676,97.0
45.178570454,95.0
45.235866232,90.0
45.293162010,116.0
45.350457788,101.0
45.407753566,105.0
45.465049344,99.0
45.522345122,96.0
45.579640899,102.0
45.636936677,91.0
45.694232455,99.0
45.751528233,109.0
45.808824011,108.0
45.866119789,114.0
45.923415567,85.0
45.980711345,111.0
46.038007123,105.0
46.095302901,93.0
46.152598679,105.0
46.209894457,102.0
46.267190235,95.0
46.324486013,85.0
46.381781791,101.0
46.439077568,73.0
46.496373346,75.0
46.553669124,106.0
46.610964902,86.0
46.668260680,91.0
46.725556458,80.0
46.782852236,101.0
46.840148014,91.0
46.897443792,83.0
46.954739570,90.0
47.012035348,98.0
47.069331126,79.0
47.126626904,91.0
47.183922682,101.0
47.241218460,88.0
47.298514238,92.0
47.355810015,101.0
47.413105793,98.0
47.470401571,103.0
47.527697349,68.0
47.584993127,73.0
47.642288905,94.0
47.699584683,92.0
47.756880461,100.0
47.814176239,81.0
47.871472017,87.0
47.928767795,84.0
47.986063573,93.0
48.043359351,90.0
48.100655129,87.0
48.157950907,85.0
48.215246685,91.0
48.272542462,65.0
48.329838240,76.0
48.387134018,74.0
48.444429796,89.0
48.501725574,68.0
48.559021352,85.0
48.616317130,90.0
48.673612908,72.0
48.730908686,75.0
48.788204464,100.0
48.845500242,75.0
48.902796020,85.0
48.960091798,70.0
49.017387576,84.0
49.074683354,84.0
49.131979131,88.0
49.189274909,81.0
49.246570687,68.0
49.303866465,71.0
49.361162243,86.0
49.418458021,89.0
49.475753799,84.0
49.533049577,65.0
49.590345355,76.0
49.647641133,61.0
49.704936911,68.0
49.762232689,94.0
49.819528467,86.0
49.876824245,81.0
49.934120023,86.0
49.991415801,73.0
50.048711578,92.0
50.106007356,82.0
50.163303134,68.0
50.220598912,68.0
50.277894690,69.0
50.335190468,75.0
50.392486246,88.0
50.449782024,66.0
50.507077802,72.0
50.564373580,73.0
50.621669358,77.0
50.678965136,76.0
50.736260914,68.0
50.793556692,95.0
50.850852470,73.0
50.908148247,74.0
50.965444025,75.0
51.022739803,93.0
51.080035581,73.0
51.137331359,73.0
51.194627137,70.0
51.251922915,74.0
51.309218693,78.0
51.366514471,76.0
51.423810249,68.0
51.481106027,95.0
51.538401805,69.0
51.595697583,107.0
51.652993361,59.0
51.710289139,79.0
51.767584917,75.0
51.824880694,76.0
51.882176472,68.0
51.939472250,100.0
51.996768028,73.0
52.054063806,91.0
52.111359584,74.0
52.168655362,74.0
52.225951140,80.0
52.283246918,75.0
52.340542696,88.0
52.397838474,82.0
52.455134252,89.0
52.512430030,95.0
52.569725808,85.0
52.627021586,110.0
52.684317364,95.0
52.741613141,112.0
52.798908919,117.0
52.856204697,136.0
52.913500475,162.0
52.970796253,186.0
53.028092031,358.0
53.085387809,572.0
53.142683587,984.0
53.199979365,1645.0
53.257275143,2564.0
53.314570921,3274.0
53.371866699,3066.0
53.429162477,2408.0
53.486458255,1778.0
53.543754033,1056.0
53.601049810,431.0
53.658345588,246.0
53.715641366,176.0
53.772937144,125.0
53.830232922,119.0
53.887528700,111.0
53.944824478,85.0
54.002120256,96.0
54.059416034,95.0
54.116711812,106.0
54.174007590,76.0
54.231303368,76.0
54.288599146,79.0
54.345894924,83.0
54.403190702,89.0
54.460486480,79.0
54.517782257,74.0
54.575078035,72.0
54.632373813,78.0
54.689669591,80.0
54.746965369,76.0
54.804261147,74.0
54.861556925,67.0
54.918852703,64.0
54.976148481,78.0
55.033444259,103.0
55.090740037,57.0
55.148035815,67.0
55.205331593,58.0
55.262627371,67.0
55.319923149,74.0
55.377218926,72.0
55.434514704,68.0
55.491810482,80.0
55.549106260,62.0
55.606402038,77.0
55.663697816,88.0
55.720993594,79.0
55.778289372,66.0
55.835585150,70.0
55.892880928,71.0
55.950176706,58.0
56.007472484,71.0
56.064768262,76.0
56.122064040,79.0
56.179359818,85.0
56.236655596,64.0
56.293951373,86.0
56.351247151,74.0
56.408542929,86.0
56.465838707,66.0
56.523134485,90.0
56.580430263,91.0
56.637726041,95.0
56.695021819,104.0
56.752317597,138.0
56.809613375,165.0
56.866909153,160.0
56.924204931,173.0
56.981500709,216.0
57.038796487,298.0
57.096092265,370.0
57.153388043,433.0
57.210683820,539.0
57.267979598,603.0
57.325275376,658.0
57.382571154,686.0
57.439866932,716.0
57.497162710,664.0
57.554458488,629.0
57.611754266,507.0
57.669050044,499.0
57.726345822,417.0
57.783641600,333.0
57.840937378,272.0
57.898233156,254.0
57.955528934,215.0
58.012824712,202.0
58.070120489,157.0
58.127416267,157.0
58.184712045,122.0
58.242007823,133.0
58.299303601,113.0
58.356599379,122.0
58.413895157,87.0
58.471190935,90.0
58.528486713,84.0
58.585782491,81.0
58.643078269,99.0
58.700374047,84.0
58.757669825,93.0
58.814965603,74.0
58.872261381,61.0
58.929557159,76.0
58.986852936,67.0
59.044148714,66.0
59.101444492,63.0
59.158740270,66.0
59.216036048,62.0
59.273331826,62.0
59.330627604,66.0
59.387923382,57.0
59.445219160,61.0
59.502514938,73.0
59.559810716,61.0
59.617106494,70.0
59.674402272,54.0
59.731698050,53.0
59.788993828,56.0
59.846289606,70.0
59.903585383,67.0
59.960881161,58.0
60.018176939,68.0
60.075472717,67.0
60.132768495,58.0
60.190064273,64.0
60.247360051,53.0
60.304655829,64.0
60.361951607,47.0
60.419247385,66.0
60.476543163,59.0
60.533838941,70.0
60.591134719,80.0
60.648430497,57.0
60.705726275,75.0
60.763022052,73.0
60.820317830,49.0
60.877613608,52.0
60.934909386,56.0
60.992205164,71.0
61.049500942,61.0
61.106796720,46.0
61.164092498,61.0
61.221388276,60.0
61.278684054,69.0
61.335979832,55.0
61.393275610,72.0
61.450571388,42.0
61.507867166,63.0
61.565162944,60.0
61.622458722,72.0
61.679754499,69.0
61.737050277,70.0
61.794346055,58.0
61.851641833,63.0
61.908937611,74.0
61.966233389,58.0
62.023529167,67.0
62.080824945,61.0
62.138120723,55.0
62.195416501,64.0
62.252712279,55.0
62.310008057,75.0
62.367303835,76.0
62.424599613,96.0
62.481895391,77.0
62.539191168,71.0
62.596486946,90.0
62.653782724,81.0
62.711078502,88.0
62.768374280,81.0
62.825670058,84.0
62.882965836,96.0
62.940261614,104.0
62.997557392,118.0
63.054853170,144.0
63.112148948,191.0
63.169444726,277.0
63.226740504,383.0
63.284036282,643.0
63.341332060,992.0
63.398627838,1497.0
63.455923615,1970.0
63.513219393,1985.0
63.570515171,1849.0
63.627810949,1607.0
63.685106727,1155.0
63.742402505,874.0
63.799698283,503.0
63.856994061,275.0
63.914289839,184.0
63.971585617,140.0
64.028881395,123.0
64.086177173,90.0
64.143472951,93.0
64.200768729,74.0
64.258064507,67.0
64.315360285,72.0
64.372656062,79.0
64.429951840,56.0
64.487247618,71.0
64.544543396,60.0
64.601839174,68.0
64.659134952,62.0
64.716430730,65.0
64.773726508,67.0
64.831022286,67.0
64.888318064,67.0
64.945613842,66.0
65.002909620,73.0
65.060205398,66.0
65.117501176,57.0
65.174796954,55.0
65.232092731,57.0
65.289388509,64.0
65.346684287,65.0
65.403980065,49.0
65.461275843,41.0
65.518571621,44.0
65.575867399,57.0
65.633163177,47.0
65.690458955,48.0
65.747754733,55.0
65.805050511,53.0
65.862346289,58.0
65.919642067,70.0
65.976937845,65.0
66.034233623,52.0
66.091529401,50.0
66.148825178,47.0
66.206120956,39.0
66.263416734,34.0
66.320712512,51.0
66.378008290,51.0
66.435304068,53.0
66.492599846,50.0
66.549895624,55.0
66.607191402,52.0
66.664487180,49.0
66.721782958,44.0
66.779078736,51.0
66.836374514,57.0
66.893670292,40.0
66.950966070,46.0
67.008261848,64.0
67.065557625,48.0
67.122853403,41.0
67.180149181,55.0
67.237444959,50.0
67.294740737,43.0
67.352036515,41.0
67.409332293,55.0
67.466628071,48.0
67.523923849,48.0
67.581219627,41.0
67.638515405,61.0
67.695811183,48.0
67.753106961,51.0
67.810402739,55.0
67.867698517,41.0
67.924994294,37.0
67.982290072,45.0
68.039585850,32.0
68.096881628,41.0
68.154177406,42.0
68.211473184,38.0
68.268768962,47.0
68.326064740,48.0
68.383360518,44.0
68.440656296,58.0
68.497952074,56.0
68.555247852,62.0
68.612543630,46.0
68.669839408,45.0
68.727135186,54.0
68.784430964,59.0
68.841726741,44.0
68.899022519,40.0
68.956318297,50.0
69.013614075,51.0
69.070909853,44.0
69.128205631,59.0
69.185501409,49.0
69.242797187,48.0
69.300092965,52.0
69.357388743,42.0
69.414684521,54.0
69.471980299,52.0
69.529276077,45.0
69.586571855,45.0
69.643867633,40.0
69.701163410,44.0
69.758459188,52.0
69.815754966,42.0
69.873050744,46.0
69.930346522,49.0
69.987642300,56.0
70.044938078,40.0
70.102233856,46.0
70.159529634,40.0
70.216825412,39.0
70.274121190,58.0
70.331416968,51.0
70.388712746,51.0
70.446008524,50.0
70.503304302,37.0
70.560600080,63.0
70.617895857,60.0
70.675191635,51.0
70.732487413,91.0
70.789783191,106.0
70.847078969,170.0
70.904374747,240.0
70.961670525,296.0
71.018966303,364.0
71.076262081,357.0
71.133557859,280.0
71.190853637,217.0
71.248149415,245.0
71.305445193,177.0
71.362740971,116.0
71.420036749,84.0
71.477332527,56.0
71.534628304,43.0
71.591924082,52.0
71.649219860,65.0
71.706515638,54.0
71.763811416,43.0
71.821107194,49.0
71.878402972,50.0
71.935698750,44.0
71.992994528,52.0
72.050290306,43.0
72.107586084,48.0
72.164881862,44.0
72.222177640,45.0
72.279473418,47.0
72.336769196,55.0
72.394064973,37.0
72.451360751,48.0
72.508656529,41.0
72.565952307,43.0
72.623248085,48.0
72.680543863,42.0
72.737839641,46.0
72.795135419,38.0
72.852431197,51.0
72.909726975,47.0
72.967022753,47.0
73.024318531,40.0
73.081614309,47.0
73.138910087,49.0
73.196205865,41.0
73.253501643,41.0
73.310797420,53.0
73.368093198,46.0
73.425388976,44.0
73.482684754,45.0
73.539980532,39.0
73.597276310,47.0
73.654572088,53.0
73.711867866,51.0
73.769163644,47.0
73.826459422,49.0
73.883755200,42.0
73.941050978,48.0
73.998346756,43.0
74.055642534,43.0
74.112938312,43.0
74.170234089,39.0
74.227529867,45.0
74.284825645,47.0
74.342121423,41.0
74.399417201,47.0
74.456712979,39.0
74.514008757,32.0
74.571304535,37.0
74.628600313,47.0
74.685896091,51.0
74.743191869,32.0
74.800487647,46.0
74.857783425,45.0
74.915079203,47.0
74.972374981,41.0
75.029670759,34.0
75.086966536,35.0
75.144262314,53.0
75.201558092,48.0
75.258853870,38.0
75.316149648,46.0
75.373445426,42.0
75.430741204,43.0
75.488036982,37.0
75.545332760,44.0
75.602628538,43.0
75.659924316,53.0
75.717220094,38.0
75.774515872,38.0
75.831811650,46.0
75.889107428,33.0
75.946403206,35.0
76.003698983,47.0
76.060994761,31.0
76.118290539,49.0
76.175586317,39.0
76.232882095,38.0
76.290177873,41.0
76.347473651,45.0
76.404769429,52.0
76.462065207,36.0
76.519360985,44.0
76.576656763,47.0
76.633952541,45.0
76.691248319,41.0
76.748544097,42.0
76.805839875,50.0
76.863135652,48.0
76.920431430,45.0
76.977727208,52.0
77.035022986,53.0
77.092318764,42.0
77.149614542,45.0
77.206910320,41.0
77.264206098,42.0
77.321501876,38.0
77.378797654,38.0
77.436093432,43.0
77.493389210,31.0
77.550684988,39.0
77.607980766,32.0
77.665276544,35.0
77.722572322,40.0
77.779868099,42.0
77.837163877,42.0
77.894459655,48.0
77.951755433,50.0
78.009051211,40.0
78.066346989,36.0
78.123642767,41.0
78.180938545,47.0
78.238234323,40.0
78.295530101,38.0
78.352825879,33.0
78.410121657,28.0
78.467417435,40.0
78.524713213,38.0
78.582008991,44.0
78.639304769,46.0
78.696600546,54.0
78.753896324,26.0
78.811192102,52.0
78.868487880,49.0
78.925783658,46.0
78.983079436,31.0
79.040375214,50.0
79.097670992,43.0
79.154966770,46.0
79.212262548,40.0
79.269558326,34.0
79.326854104,43.0
79.384149882,40.0
79.441445660,35.0
79.498741438,32.0
79.556037215,31.0
79.613332993,34.0
79.670628771,35.0
79.727924549,51.0
79.785220327,33.0
79.842516105,44.0
79.899811883,47.0
79.957107661,51.0
79.985755550,40.0